Workbook

Sheet 1A
A1: Rbr. | B1: Ime učenika | C1: Prezime učenika | D1: Datum rođenja | E1: Angažiranost | F1: Socio-ekonomski status | G1: Radne navike | H1: Podrška obitelji | I1: Napomene učiteljice | J1: Login | K1: Identifikator tableta | L1: Tip tableta
A2: 1 | B2: AZER | C2: BEŠIĆ | D2: 15.01.2009. | E2: Slaba | F2: Nizak | G2: Srednje | H2: Mala | I2: - | J2: abesic | K2: AND_1 | L2: Android | N2: Slaba | O2: Nizak | P2: Loše | Q2: Mala
A3: 2 | B3: DORA | C3: BUKAL | D3: 01.12.2008. | E3: Srednja | F3: Visok | G3: Dobre | H3: Velika | I3: Prosječna | J3: dbukal | K3: AND_2 | L3: Android | N3: Srednja | O3: Srednji | P3: Srednje | Q3: Srednja
A4: 3 | B4: GABRIELA | C4: CIKAČ | D4: 05.05.2008. | E4: Srednja | F4: Nizak | G4: Srednje | H4: Mala | I4: - | J4: gcikac | K4: AND_3 | L4: Android | N4: Jaka | O4: Visok | P4: Dobre | Q4: Velika
A5: 4 | B5: LANA | C5: DOBRILOVIĆ | D5: 09.01.2009. | E5: Srednja | F5: Srednji | G5: Dobre | H5: Velika | I5: Prosječna | J5: ldobrijevic | K5: AND_4 | L5: Android
A6: 5 | B6: ANJA | C6: DŽAKULA | D6: 25.06.2008. | E6: Jaka | F6: Visok | G6: Dobre | H6: Velika | I6: Iznadprosječna | J6: adzakula | K6: AND_5 | L6: Android
A7: 6 | B7: STJEPAN | C7: FILOTAŠ | D7: 18.11.2008. | E7: Slaba | F7: Nizak | G7: Loše | H7: Mala | I7: - | J7: sfilotas | K7: AND_6 | L7: Android
A8: 7 | B8: ADRIAN | C8: HRUBI | D8: 02.04.2008. | E8: Srednja | F8: Srednji | G8: Loše | H8: Srednja | I8: ADHD (nediagnosticiran) | J8: ahrubi | K8: AND_7 | L8: Android
A9: 8 | B9: VITA | C9: JERGOVIĆ | D9: 23.02.2008. | E9: Srednja | F9: Visok | G9: Loše | H9: Velika | I9: ADHD | J9: vjergovic | K9: AND_8 | L9: Android
A10: 9 | B10: KORINA | C10: MATOŠEVIĆ | D10: 23.01.2009. | E10: Jaka | F10: Srednji | G10: Srednje | H10: Srednja | I10: Prosječna | J10: kmatosevic | K10: AND_9 | L10: Android
A11: 10 | B11: BARBARA | C11: MIKOVIĆ | D11: 22.09.2008. | E11: Srednja | F11: Srednji | G11: Loše | H11: Srednja | I11: - | J11: bmikovic | K11: AND_10 | L11: Android
A12: 11 | B12: FILIP | C12: PERESTEGI | D12: 30.06.2008. | E12: Jaka | F12: Visok | G12: Dobre | H12: Velika | I12: Iznadprosječan | J12: fperestegi | K12: AND_11 | L12: Android
A13: 12 | B13: LARA | C13: SHEK BRNARDIĆ | D13: 08.04.2008. | E13: Slaba | F13: Visok | G13: Dobre | H13: Velika | I13: Downov sindrom | J13: lshek | K13: AND_12 | L13: Android
A14: 13 | B14: MARIN | C14: ŠEGO | D14: 25.03.2009. | E14: Jaka | F14: Visok | G14: Dobre | H14: Srednja | I14: Iznadprosječan | J14: msego | K14: WIN_1 | L14: Windows
A15: 14 | B15: LAURA | C15: ŠUG | D15: 31.03.2009. | E15: Slaba | F15: Visok | G15: Srednje | H15: Srednja | I15: Neobična situacija | J15: lsug | K15: WIN_2 | L15: Windows
A16: 15 | B16: ROBERTINO | C16: VEREŠ | D16: 04.11.2008. | E16: Slaba | F16: Nizak | G16: Loše | H16: Mala | I16: - | J16: rveres | K16: WIN_3 | L16: Windows
... A19: 18 | B19: VITO | C19: ZAVRTNIK | D19: 28.08.2008. | E19: Srednja | F19: Visok | G19: Srednje | H19: Srednja | I19: Prosječan | J19: vzavrtnik | K19: IOS_3 | L19: iOS

Sheet 1B
A1: Rbr. | B1: Ime učenika | C1: Prezime učenika | D1: Datum rođenja | E1: Angažiranost | F1: Socio-ekonomski status | G1: Radne navike | H1: Podrška obitelji | I1: Napomene učiteljice | J1: Login | K1: Identifikator tableta | L1: Tip tableta
A2: 1 | B2: ADRIJANA | C2: BERC | D2: 11. 05. 2008. | E2: Srednja | F2: Srednji | G2: Dobre | H2: Mala | I2: - | J2: aberc | K2: AND_13 | L2: Android | N2: Slaba | O2: Nizak | P2: Loše | Q2: Mala
A3: 2 | B3: ANDRIJA | C3: BILOGLAV | D3: 04. 04. 2008. | E3: Slaba | F3: Srednji | G3: Srednje | H3: Velika | I3: - | J3: abiloglav | K3: AND_14 | L3: Android | N3: Srednja | O3: Srednji | P3: Srednje | Q3: Srednja
A4: 3 | B4: LUKA | C4: ĐURIK | D4: 24. 08. 2008. | E4: Jaka | F4: Visok | G4: Dobre | H4: Velika | I4: Iznadprosječan | J4: ldurik | K4: AND_15 | L4: Android | N4: Jaka | O4: Visok | P4: Dobre | Q4: Velika
A5: 4 | B5: EVA | C5: GLAVINIĆ | D5: 03. 03. 2009. | E5: Srednja | F5: Visok | G5: Dobre | H5: Velika | I5: - | J5: eglavinic | K5: AND_16 | L5: Android
A6: 5 | B6: BENJAMIN | C6: HADŽIĆ | D6: 01. 08. 2008. | E6: Srednja | F6: Nizak | G6: Dobre | H6: Velika | I6: Iznadprosječan | J6: bhadzic | K6: AND_17 | L6: Android
A7: 6 | B7: ANAMARIJA | C7: KNEŽEVIĆ | D7: 12. 05. 2009. | E7: Slaba | F7: Visok | G7: Dobre | H7: Velika | I7: - | J7: aknezevic | K7: AND_18 | L7: Android
A8: 7 | B8: LARA | C8: MAJER | D8: 12. 08. 2008. | E8: Slaba | F8: Visok | G8: Dobre | H8: Velika | I8: Iznadprosječna | J8: lmajer | K8: AND_19 | L8: Android
A9: 8 | B9: VILIM | C9: MARTINIS | D9: 18. 08. 2008. | E9: Srednja | F9: Srednji | G9: Dobre | H9: Velika | I9: Iznadprosječan + Asperger | J9: vmartinis | K9: AND_20 | L9: Android
A10: 9 | B10: NINA | C10: MATE | D10: 30. 08. 2008. | E10: Srednja | F10: Srednji | G10: Dobre | H10: Srednja | I10: - | J10: nmate | K10: AND_21 | L10: Android
A11: 10 | B11: MATEA | C11: MELHER | D11: 11. 02. 2009. | E11: Jaka | F11: Visok | G11: Dobre | H11: Velika | I11: - | J11: mmelher | K11: AND_22 | L11: Android
A12: 11 | B12: KATARINA | C12: OMRČANIN | D12: 23. 10. 2008. | E12: Jaka | F12: Visok | G12: Dobre | H12: Velika | I12: - | J12: komrcanin | K12: AND_23 | L12: Android
A13: 12 | B13: JANA | C13: OSMAK | D13: 30. 01. 2009. | E13: Slaba | F13: Visok | G13: Srednje | H13: Velika | I13: - | J13: josmak | K13: WIN_4 | L13: Windows
A14: 13 | B14: DINO | C14: RIZVANOVIĆ ALVEDIN | D14: 12. 06. 2008. | E14: Slaba | F14: Nizak | G14: Loše | H14: Mala | I14: ADHD | J14: drizvanovicalvedin | K14: WIN_5 | L14: Windows
A15: 14 | B15: FILIP | C15: SEKELJ | D15: 09. 04. 2009. | E15: Slaba | F15: Visok | G15: Srednje | H15: Velika | I15: - | J15: fsekelj | K15: WIN_6 | L15: Windows
A16: 15 | B16: ELA | C16: SORIĆ | D16: 19. 11. 2008. | E16: Srednja | F16: Srednji | G16: Srednje | H16: Srednja | I16: - | J16: elasoric | K16: IOS_4 | L16: iOS
... A18: 17 | B18: IVAN | C18: VUJNOVIĆ | D18: 01. 03. 2009. | E18: Slaba | F18: Nizak | G18: Loše | H18: Mala | I18: - | J18: ivujnovic | K18: IOS_6 | L18: iOS

Sheet 2
A1: Rbr. | B1: Ime učenika | C1: Prezime učenika | D1: Datum rođenja | E1: Angažiranost | F1: Socio-ekonomski status | G1: Radne navike | H1: Podrška obitelji | I1: Identifikator tableta | J1: Tip tableta
A2: 1 | B2: JANA | C2: BRADVICA | E2: Srednja | F2: Visok | G2: Srednje | H2: Velika | I2: AND_24 | J2: Android | L2: Slaba | M2: Nizak | N2: Loše | O2: Mala
A3: 2 | B3: TIA | C3: BRTAN | E3: Srednja | F3: Srednji | G3: Loše | H3: Mala | I3: AND_25 | J3: Android | L3: Srednja | M3: Srednji | N3: Srednje | O3: Srednja
A4: 3 | B4: TENA | C4: BUKOVAC | E4: Srednja | F4: Nizak | G4: Dobre | H4: Srednja | I4: AND_26 | J4: Android | L4: Jaka | M4: Visok | N4: Dobre | O4: Velika
A5: 4 | B5: EMANUEL | C5: ČAJSA | E5: Slaba | F5: Nizak | G5: Loše | H5: Mala | I5: AND_27 | J5: Android
A6: 5 | B6: STIPE | C6: ČULINA | E6: Jaka | F6: Srednji | G6: Dobre | H6: Velika | I6: AND_28 | J6: Android
A7: 6 | B7: BRUNO | C7: ĆURČIĆ | E7: Jaka | F7: Srednji | G7: Dobre | H7: Velika | I7: AND_29 | J7: Android
A8: 7 | B8: VITO | C8: ĆURČIĆ | E8: Srednja | F8: Srednji | G8: Srednje | H8: Velika | I8: AND_30 | J8: Android
A9: 8 | B9: IVAN | C9: DEKOVIĆ | E9: Srednja | F9: Srednji | G9: Dobre | H9: Velika | I9: AND_31 | J9: Android
A10: 9 | B10: ALAN | C10: DIKLIĆ | E10: Jaka | F10: Visok | G10: Srednje | H10: Velika | I10: AND_32 | J10: Android
A11: 10 | B11: ROKO | C11: DUIĆ | E11: Srednja | F11: Srednji | G11: Loše | H11: Velika | I11: AND_33 | J11: Android
A12: 11 | B12: FRAN | C12: FILIPOVIĆ | E12: Srednja | F12: Srednji | G12: Srednje | H12: Srednja | I12: AND_34 | J12: Android
A13: 12 | B13: LEON | C13: HOTKO | E13: Jaka | F13: Srednji | G13: Dobre | H13: Velika | I13: AND_35 | J13: Android
A14: 13 | B14: ALINA | C14: JANDRIĆ | E14: Srednja | F14: Visok | G14: Srednje | H14: Srednja | I14: AND_36 | J14: Android
A15: 14 | B15: MAŠA | C15: KLASIĆ | E15: Jaka | F15: Visok | G15: Dobre | H15: Velika | I15: AND_37 | J15: Android
A16: 15 | B16: SIMON | C16: LEŠ | E16: Srednja | F16: Nizak | G16: Srednje | H16: Srednja | I16: AND_38 | J16: Android
... A24: 23 | B24: LEON | C24: VUJNOVIĆ | E24: Srednja | F24: Srednji | G24: Srednje | H24: Mala | I24: IOS_9 | J24: iOS

Sheet 3
A1: Rbr. | B1: Ime učenika | C1: Prezime učenika | D1: Datum rođenja | E1: Angažiranost | F1: Socio-ekonomski status | G1: Radne navike | H1: Podrška obitelji | I1: Identifikator tableta | J1: Tip tableta
A2: 1 | B2: ANTONIJA | C2: BUČKAL | I2: AND_24 | J2: Android | L2: Slaba | M2: Nizak | N2: Loše | O2: Mala
A3: 2 | B3: LORENA | C3: DOMANČIĆ | I3: AND_25 | J3: Android | L3: Srednja | M3: Srednji | N3: Srednje | O3: Srednja
A4: 3 | B4: LEA | C4: DVOJKOVIĆ | I4: AND_26 | J4: Android | L4: Jaka | M4: Visok | N4: Dobre | O4: Velika
A5: 4 | B5: TONKA | C5: FERDEBAR | I5: AND_27 | J5: Android
A6: 5 | B6: ANDELON | C6: FILOTAŠ | I6: AND_28 | J6: Android
A7: 6 | B7: LUKA | C7: FRANIĆ | I7: AND_29 | J7: Android
A8: 7 | B8: FRAN | C8: GLAS | I8: AND_30 | J8: Android
A9: 8 | B9: GITA | C9: HAINSKI | I9: AND_31 | J9: Android
A10: 9 | B10: MIA | C10: HRANILOVIĆ | I10: AND_32 | J10: Android
A11: 10 | B11: GABRIELA | C11: JAGAR | I11: AND_33 | J11: Android
A12: 11 | B12: ISKRA | C12: JAKOB | I12: AND_34 | J12: Android
A13: 12 | B13: LOVRO | C13: KAIĆ | I13: AND_35 | J13: Android
A14: 13 | B14: OMAR | C14: KARALIĆ | I14: AND_36 | J14: Android
A15: 14 | B15: LEON | C15: MATE | I15: AND_37 | J15: Android
A16: 15 | B16: DAVID | C16: MATOŠEVIĆ | I16: AND_38 | J16: Android
... A25: 24 | B25: MATEA | C25: ZVONKOVIĆ | I25: IOS_10 | J25: iOS

Sheet Import_svi
A1: abesic | B1: AZER BEŠIĆ | D1: OST-1516-1A
A2: dbukal | B2: DORA BUKAL | D2: OST-1516-1A
A3: gcikac | B3: GABRIELA CIKAČ | D3: OST-1516-1A
A4: ldobrijevic | B4: LANA DOBRILOVIĆ | D4: OST-1516-1A
A5: adzakula | B5: ANJA DŽAKULA | D5: OST-1516-1A
A6: sfilotas | B6: STJEPAN FILOTAŠ | D6: OST-1516-1A
A7: ahrubi | B7: ADRIAN HRUBI | D7: OST-1516-1A
A8: vjergovic | B8: VITA JERGOVIĆ | D8: OST-1516-1A
A9: kmatosevic | B9: KORINA MATOŠEVIĆ | D9: OST-1516-1A
A10: bmikovic | B10: BARBARA MIKOVIĆ | D10: OST-1516-1A
A11: fperestegi | B11: FILIP PERESTEGI | D11: OST-1516-1A
A12: lshek | B12: LARA SHEK BRNARDIĆ | D12: OST-1516-1A
... A82: mzvonkovic | B82: MATEA ZVONKOVIĆ | D82: OST-1516-3

Sheet Naljepnice
A1: UREĐAJ: | B1: ='1A'!$K2 -> AND_1 | C1: 1A | D1: UREĐAJ: | E1: ='1B'!$K2 -> AND_13 | F1: 1B | G1: UREĐAJ: | H1: ='2'!$I2 -> AND_24 | I1: 2 | J1: UREĐAJ: | K1: ='3'!$I2 -> AND_24 | L1: 3
A2: IME: | B2: ='1A'!$C2 -> BEŠIĆ | C2: ='1A'!$B2 -> AZER | D2: IME: | E2: ='1B'!$C2 -> BERC | F2: ='1B'!$B2 -> ADRIJANA | G2: IME: | H2: ='2'!$C2 -> BRADVICA | I2: ='2'!$B2 -> JANA | J2: IME: | K2: ='3'!$C2 -> BUČKAL | L2: ='3'!$B2 -> ANTONIJA
A3: UREĐAJ: | B3: ='1A'!$K3 -> AND_2 | C3: 1A | D3: UREĐAJ: | E3: ='1B'!$K3 -> AND_14 | F3: 1B | G3: UREĐAJ: | H3: ='2'!$I3 -> AND_25 | I3: 2 | J3: UREĐAJ: | K3: ='3'!$I3 -> AND_25 | L3: 3
A4: IME: | B4: ='1A'!$C3 -> BUKAL | C4: ='1A'!$B3 -> DORA | D4: IME: | E4: ='1B'!$C3 -> BILOGLAV | F4: ='1B'!$B3 -> ANDRIJA | G4: IME: | H4: ='2'!$C3 -> BRTAN | I4: ='2'!$B3 -> TIA | J4: IME: | K4: ='3'!$C3 -> DOMANČIĆ | L4: ='3'!$B3 -> LORENA
A5: UREĐAJ: | B5: ='1A'!$K4 -> AND_3 | C5: 1A | D5: UREĐAJ: | E5: ='1B'!$K4 -> AND_15 | F5: 1B | G5: UREĐAJ: | H5: ='2'!$I4 -> AND_26 | I5: 2 | J5: UREĐAJ: | K5: ='3'!$I4 -> AND_26 | L5: 3
A6: IME: | B6: ='1A'!$C4 -> CIKAČ | C6: ='1A'!$B4 -> GABRIELA | D6: IME: | E6: ='1B'!$C4 -> ĐURIK | F6: ='1B'!$B4 -> LUKA | G6: IME: | H6: ='2'!$C4 -> BUKOVAC | I6: ='2'!$B4 -> TENA | J6: IME: | K6: ='3'!$C4 -> DVOJKOVIĆ | L6: ='3'!$B4 -> LEA
A7: UREĐAJ: | B7: ='1A'!$K5 -> AND_4 | C7: 1A | D7: UREĐAJ: | E7: ='1B'!$K5 -> AND_16 | F7: 1B | G7: UREĐAJ: | H7: ='2'!$I5 -> AND_27 | I7: 2 | J7: UREĐAJ: | K7: ='3'!$I5 -> AND_27 | L7: 3
A8: IME: | B8: ='1A'!$C5 -> DOBRILOVIĆ | C8: ='1A'!$B5 -> LANA | D8: IME: | E8: ='1B'!$C5 -> GLAVINIĆ | F8: ='1B'!$B5 -> EVA | G8: IME: | H8: ='2'!$C5 -> ČAJSA | I8: ='2'!$B5 -> EMANUEL | J8: IME: | K8: ='3'!$C5 -> FERDEBAR | L8: ='3'!$B5 -> TONKA
A9: UREĐAJ: | B9: ='1A'!$K6 -> AND_5 | C9: 1A | D9: UREĐAJ: | E9: ='1B'!$K6 -> AND_17 | F9: 1B | G9: UREĐAJ: | H9: ='2'!$I6 -> AND_28 | I9: 2 | J9: UREĐAJ: | K9: ='3'!$I6 -> AND_28 | L9: 3
A10: IME: | B10: ='1A'!$C6 -> DŽAKULA | C10: ='1A'!$B6 -> ANJA | D10: IME: | E10: ='1B'!$C6 -> HADŽIĆ | F10: ='1B'!$B6 -> BENJAMIN | G10: IME: | H10: ='2'!$C6 -> ČULINA | I10: ='2'!$B6 -> STIPE | J10: IME: | K10: ='3'!$C6 -> FILOTAŠ | L10: ='3'!$B6 -> ANDELON
A11: UREĐAJ: | B11: ='1A'!$K7 -> AND_6 | C11: 1A | D11: UREĐAJ: | E11: ='1B'!$K7 -> AND_18 | F11: 1B | G11: UREĐAJ: | H11: ='2'!$I7 -> AND_29 | I11: 2 | J11: UREĐAJ: | K11: ='3'!$I7 -> AND_29 | L11: 3
A12: IME: | B12: ='1A'!$C7 -> FILOTAŠ | C12: ='1A'!$B7 -> STJEPAN | D12: IME: | E12: ='1B'!$C7 -> KNEŽEVIĆ | F12: ='1B'!$B7 -> ANAMARIJA | G12: IME: | H12: ='2'!$C7 -> ĆURČIĆ | I12: ='2'!$B7 -> BRUNO | J12: IME: | K12: ='3'!$C7 -> FRANIĆ | L12: ='3'!$B7 -> LUKA
A13: UREĐAJ: | B13: ='1A'!$K8 -> AND_7 | C13: 1A | D13: UREĐAJ: | E13: ='1B'!$K8 -> AND_19 | F13: 1B | G13: UREĐAJ: | H13: ='2'!$I8 -> AND_30 | I13: 2 | J13: UREĐAJ: | K13: ='3'!$I8 -> AND_30 | L13: 3
A14: IME: | B14: ='1A'!$C8 -> HRUBI | C14: ='1A'!$B8 -> ADRIAN | D14: IME: | E14: ='1B'!$C8 -> MAJER | F14: ='1B'!$B8 -> LARA | G14: IME: | H14: ='2'!$C8 -> ĆURČIĆ | I14: ='2'!$B8 -> VITO | J14: IME: | K14: ='3'!$C8 -> GLAS | L14: ='3'!$B8 -> FRAN
A15: UREĐAJ: | B15: ='1A'!$K9 -> AND_8 | C15: 1A | D15: UREĐAJ: | E15: ='1B'!$K9 -> AND_20 | F15: 1B | G15: UREĐAJ: | H15: ='2'!$I9 -> AND_31 | I15: 2 | J15: UREĐAJ: | K15: ='3'!$I9 -> AND_31 | L15: 3
A16: IME: | B16: ='1A'!$C9 -> JERGOVIĆ | C16: ='1A'!$B9 -> VITA | D16: IME: | E16: ='1B'!$C9 -> MARTINIS | F16: ='1B'!$B9 -> VILIM | G16: IME: | H16: ='2'!$C9 -> DEKOVIĆ | I16: ='2'!$B9 -> IVAN | J16: IME: | K16: ='3'!$C9 -> HAINSKI | L16: ='3'!$B9 -> GITA
A17: UREĐAJ: | B17: ='1A'!$K10 -> AND_9 | C17: 1A | D17: UREĐAJ: | E17: ='1B'!$K10 -> AND_21 | F17: 1B | G17: UREĐAJ: | H17: ='2'!$I10 -> AND_32 | I17: 2 | J17: UREĐAJ: | K17: ='3'!$I10 -> AND_32 | L17: 3
A18: IME: | B18: ='1A'!$C10 -> MATOŠEVIĆ | C18: ='1A'!$B10 -> KORINA | D18: IME: | E18: ='1B'!$C10 -> MATE | F18: ='1B'!$B10 -> NINA | G18: IME: | H18: ='2'!$C10 -> DIKLIĆ | I18: ='2'!$B10 -> ALAN | J18: IME: | K18: ='3'!$C10 -> HRANILOVIĆ | L18: ='3'!$B10 -> MIA
A19: UREĐAJ: | B19: ='1A'!$K11 -> AND_10 | C19: 1A | D19: UREĐAJ: | E19: ='1B'!$K11 -> AND_22 | F19: 1B | G19: UREĐAJ: | H19: ='2'!$I11 -> AND_33 | I19: 2 | J19: UREĐAJ: | K19: ='3'!$I11 -> AND_33 | L19: 3
A20: IME: | B20: ='1A'!$C11 -> MIKOVIĆ | C20: ='1A'!$B11 -> BARBARA | D20: IME: | E20: ='1B'!$C11 -> MELHER | F20: ='1B'!$B11 -> MATEA | G20: IME: | H20: ='2'!$C11 -> DUIĆ | I20: ='2'!$B11 -> ROKO | J20: IME: | K20: ='3'!$C11 -> JAGAR | L20: ='3'!$B11 -> GABRIELA
A21: UREĐAJ: | B21: ='1A'!$K12 -> AND_11 | C21: 1A | D21: UREĐAJ: | E21: ='1B'!$K12 -> AND_23 | F21: 1B | G21: UREĐAJ: | H21: ='2'!$I12 -> AND_34 | I21: 2 | J21: UREĐAJ: | K21: ='3'!$I12 -> AND_34 | L21: 3
A22: IME: | B22: ='1A'!$C12 -> PERESTEGI | C22: ='1A'!$B12 -> FILIP | D22: IME: | E22: ='1B'!$C12 -> OMRČANIN | F22: ='1B'!$B12 -> KATARINA | G22: IME: | H22: ='2'!$C12 -> FILIPOVIĆ | I22: ='2'!$B12 -> FRAN | J22: IME: | K22: ='3'!$C12 -> JAKOB | L22: ='3'!$B12 -> ISKRA
A23: UREĐAJ: | B23: ='1A'!$K13 -> AND_12 | C23: 1A | D23: UREĐAJ: | E23: ='1B'!$K13 -> WIN_4 | F23: 1B | G23: UREĐAJ: | H23: ='2'!$I13 -> AND_35 | I23: 2 | J23: UREĐAJ: | K23: ='3'!$I13 -> AND_35 | L23: 3
A24: IME: | B24: ='1A'!$C13 -> SHEK BRNARDIĆ | C24: ='1A'!$B13 -> LARA | D24: IME: | E24: ='1B'!$C13 -> OSMAK | F24: ='1B'!$B13 -> JANA | G24: IME: | H24: ='2'!$C13 -> HOTKO | I24: ='2'!$B13 -> LEON | J24: IME: | K24: ='3'!$C13 -> KAIĆ | L24: ='3'!$B13 -> LOVRO
A25: UREĐAJ: | B25: ='1A'!$K14 -> WIN_1 | C25: 1A | D25: UREĐAJ: | E25: ='1B'!$K14 -> WIN_5 | F25: 1B | G25: UREĐAJ: | H25: ='2'!$I14 -> AND_36 | I25: 2 | J25: UREĐAJ: | K25: ='3'!$I14 -> AND_36 | L25: 3
A26: IME: | B26: ='1A'!$C14 -> ŠEGO | C26: ='1A'!$B14 -> MARIN | D26: IME: | E26: ='1B'!$C14 -> RIZVANOVIĆ ALVEDIN | F26: ='1B'!$B14 -> DINO | G26: IME: | H26: ='2'!$C14 -> JANDRIĆ | I26: ='2'!$B14 -> ALINA | J26: IME: | K26: ='3'!$C14 -> KARALIĆ | L26: ='3'!$B14 -> OMAR
A27: UREĐAJ: | B27: ='1A'!$K15 -> WIN_2 | C27: 1A | D27: UREĐAJ: | E27: ='1B'!$K15 -> WIN_6 | F27: 1B | G27: UREĐAJ: | H27: ='2'!$I15 -> AND_37 | I27: 2 | J27: UREĐAJ: | K27: ='3'!$I15 -> AND_37 | L27: 3
A28: IME: | B28: ='1A'!$C15 -> ŠUG | C28: ='1A'!$B15 -> LAURA | D28: IME: | E28: ='1B'!$C15 -> SEKELJ | F28: ='1B'!$B15 -> FILIP | G28: IME: | H28: ='2'!$C15 -> KLASIĆ | I28: ='2'!$B15 -> MAŠA | J28: IME: | K28: ='3'!$C15 -> MATE | L28: ='3'!$B15 -> LEON
A29: UREĐAJ: | B29: ='1A'!$K16 -> WIN_3 | C29: 1A | D29: UREĐAJ: | E29: ='1B'!$K16 -> IOS_4 | F29: 1B | G29: UREĐAJ: | H29: ='2'!$I16 -> AND_38 | I29: 2 | J29: UREĐAJ: | K29: ='3'!$I16 -> AND_38 | L29: 3
A30: IME: | B30: ='1A'!$C16 -> VEREŠ | C30: ='1A'!$B16 -> ROBERTINO | D30: IME: | E30: ='1B'!$C16 -> SORIĆ | F30: ='1B'!$B16 -> ELA | G30: IME: | H30: ='2'!$C16 -> LEŠ | I30: ='2'!$B16 -> SIMON | J30: IME: | K30: ='3'!$C16 -> MATOŠEVIĆ | L30: ='3'!$B16 -> DAVID
A31: UREĐAJ: | B31: ='1A'!$K17 -> IOS_1 | C31: 1A | D31: UREĐAJ: | E31: ='1B'!$K17 -> IOS_5 | F31: 1B | G31: UREĐAJ: | H31: ='2'!$I17 -> WIN_7 | I31: 2 | J31: UREĐAJ: | K31: ='3'!$I17 -> WIN_7 | L31: 3
A32: IME: | B32: ='1A'!$C17 -> VOJNOVIĆ | C32: ='1A'!$B17 -> KIRA DIADRA | D32: IME: | E32: ='1B'!$C17 -> SORIĆ | F32: ='1B'!$B17 -> EVA | G32: IME: | H32: ='2'!$C17 -> MARCAPAN-KRESNIK | I32: ='2'!$B17 -> NATALY | J32: IME: | K32: ='3'!$C17 -> MAVRA | L32: ='3'!$B17 -> LUNA
A33: UREĐAJ: | B33: ='1A'!$K18 -> IOS_2 | C33: 1A | D33: UREĐAJ: | E33: ='1B'!#REF! -> #REF! | F33: 1B | G33: UREĐAJ: | H33: ='2'!$I18 -> WIN_8 | I33: 2 | J33: UREĐAJ: | K33: ='3'!$I18 -> WIN_8 | L33: 3
A34: IME: | B34: ='1A'!$C18 -> VUGRIN | C34: ='1A'!$B18 -> JURAJ | D34: IME: | E34: ='1B'!$C18 -> VUJNOVIĆ | F34: ='1B'!$B18 -> IVAN | G34: IME: | H34: ='2'!$C18 -> MARKUŠIĆ | I34: ='2'!$B18 -> LEONARDA | J34: IME: | K34: ='3'!$C18 -> MIHALJEVIĆ | L34: ='3'!$B18 -> MAGDALENA
A35: UREĐAJ: | B35: ='1A'!$K19 -> IOS_3 | C35: 1A | G35: UREĐAJ: | H35: ='2'!$I19 -> WIN_9 | I35: 2 | J35: UREĐAJ: | K35: ='3'!$I19 -> WIN_9 | L35: 3
A36: IME: | B36: ='1A'!$C19 -> ZAVRTNIK | C36: ='1A'!$B19 -> VITO | G36: IME: | H36: ='2'!$C19 -> PRUGOVEČKI | I36: ='2'!$B19 -> LUKA | J36: IME: | K36: ='3'!$C19 -> PERESTEGI | L36: ='3'!$B19 -> MARTA
G37: UREĐAJ: | H37: ='2'!$I20 -> WIN_10 | I37: 2 | J37: UREĐAJ: | K37: ='3'!$I20 -> WIN_10 | L37: 3
G38: IME: | H38: ='2'!$C20 -> RENDULIĆ | I38: ='2'!$B20 -> MARKS RUDOLF | J38: IME: | K38: ='3'!$C20 -> PRELOG | L38: ='3'!$B20 -> IVY
G39: UREĐAJ: | H39: ='2'!$I21 -> WIN_11 | I39: 2 | J39: UREĐAJ: | K39: ='3'!$I21 -> WIN_11 | L39: 3
G40: IME: | H40: ='2'!$C21 -> ŠIMIĆ | I40: ='2'!$B21 -> JAKOV | J40: IME: | K40: ='3'!$C21 -> SHEK BRNARDIĆ | L40: ='3'!$B21 -> LEA
...

Sheet Naljepnice AR samo droidi
A1: UREĐAJ: | B1: AR_01 | C1: 1B | E1: UREĐAJ: | F1: AR_07 | G1: 2
A2: IME: | B2: OSMAK | C2: JANA | E2: IME: | F2: MARCAPAN-KRESNIK | G2: NATALY
A3: UREĐAJ: | B3: AR_02 | C3: 1B | E3: UREĐAJ: | F3: AR_08 | G3: 2
A4: IME: | B4: RIZVANOVIĆ ALVEDIN | C4: DINO | E4: IME: | F4: MARKUŠIĆ | G4: LEONARDA
A5: UREĐAJ: | B5: AR_03 | C5: 1B | E5: UREĐAJ: | F5: AR_09 | G5: 2
A6: IME: | B6: SEKELJ | C6: FILIP | E6: IME: | F6: PRUGOVEČKI | G6: LUKA
A7: UREĐAJ: | B7: AR_04 | C7: 1B | E7: UREĐAJ: | F7: AR_10 | G7: 2
A8: IME: | B8: SORIĆ | C8: ELA | E8: IME: | F8: RENDULIĆ | G8: MARKS RUDOLF
A9: UREĐAJ: | B9: AR_05 | C9: 1B | E9: UREĐAJ: | F9: AR_11 | G9: 2
A10: IME: | B10: SORIĆ | C10: EVA | E10: IME: | F10: ŠIMIĆ | G10: JAKOV
A11: UREĐAJ: | B11: AR_06 | C11: 1B | E11: UREĐAJ: | F11: AR_12 | G11: 2
A12: IME: | B12: VUJNOVIĆ | C12: IVAN | E12: IME: | F12: TRESK | G12: KRUNO
E13: UREĐAJ: | F13: AR_13 | G13: 2
A14: Za naljepiti na tablete exclus. 2./3. r. | E14: IME: | F14: VALER | G14: MATEJ
A15: UREĐAJ: | B15: AR_15 | C15: 1A | E15: UREĐAJ: | F15: AR_14 | G15: 2
A16: IME: | B16: ŠEGO | C16: MARIN | E16: IME: | F16: VUJNOVIĆ | G16: LEON
A17: UREĐAJ: | B17: AR_16 | C17: 1A
A18: IME: | B18: ŠUG | C18: LAURA | E18: Za naljepiti na tablete 1A razreda
A19: UREĐAJ: | B19: AR_17 | C19: 1A | E19: UREĐAJ: | F19: AR_21 | G19: 2
A20: IME: | B20: VEREŠ | C20: ROBERTINO | E20: IME: | F20: MARCAPAN-KRESNIK | G20: NATALY
A21: UREĐAJ: | B21: AR_18 | C21: 1A | E21: UREĐAJ: | F21: AR_22 | G21: 2
A22: IME: | B22: VOJNOVIĆ | C22: KIRA DIADRA | E22: IME: | F22: MARKUŠIĆ | G22: LEONARDA
A23: UREĐAJ: | B23: AR_19 | C23: 1A | E23: UREĐAJ: | F23: AR_23 | G23: 2
A24: IME: | B24: VUGRIN | C24: JURAJ | E24: IME: | F24: PRUGOVEČKI | G24: LUKA
A25: UREĐAJ: | B25: AR_20 | C25: 1A | E25: UREĐAJ: | F25: AR_24 | G25: 2
A26: IME: | B26: ZAVRTNIK | C26: VITO | E26: IME: | F26: RENDULIĆ | G26: MARKS RUDOLF
E27: UREĐAJ: | F27: AR_25 | G27: 2
E28: IME: | F28: ŠIMIĆ | G28: JAKOV
E29: UREĐAJ: | F29: AR_26 | G29: 2
E30: IME: | F30: TRESK | G30: KRUNO
E31: UREĐAJ: | F31: AR_27 | G31: 2
E32: IME: | F32: VALER | G32: MATEJ
E33: UREĐAJ: | F33: AR_28 | G33: 2
E34: IME: | F34: VUJNOVIĆ | G34: LEON

Sheet Eksperiment1_Mia-3.3.-3R
A1: ID | B1: GroupName | C1: ParentGroupID | N1: GroupDrawingTask
A2: 169 | B2: Grupa-Mia-Exp1 abuckal | C2: 168 | H2: 2257 | I2: 169 | M2: 169 | N2: 27
A3: 170 | B3: Grupa-Mia-Exp1 ldomancic | C3: 168 | H3: 2258 | I3: 170 | M3: 170 | N3: 27
A4: 171 | B4: Grupa-Mia-Exp1 ldvojkovic | C4: 168 | H4: 2259 | I4: 171 | M4: 171 | N4: 27
A5: 172 | B5: Grupa-Mia-Exp1 tferdebar | C5: 168 | H5: 2260 | I5: 172 | M5: 172 | N5: 27
A6: 173 | B6: Grupa-Mia-Exp1 afilotas | C6: 168 | H6: 2261 | I6: 173 | M6: 173 | N6: 27
A7: 174 | B7: Grupa-Mia-Exp1 lfranic | C7: 168 | H7: 2262 | I7: 174 | M7: 174 | N7: 27
A8: 175 | B8: Grupa-Mia-Exp1 fglas | C8: 168 | H8: 2263 | I8: 175 | M8: 175 | N8: 27
A9: 176 | B9: Grupa-Mia-Exp1 ghainski | C9: 168 | H9: 2264 | I9: 176 | M9: 176 | N9: 27
A10: 177 | B10: Grupa-Mia-Exp1 mhranlovic | C10: 168 | H10: 2265 | I10: 177 | M10: 177 | N10: 27
A11: 178 | B11: Grupa-Mia-Exp1 gjagar | C11: 168 | H11: 2266 | I11: 178 | M11: 178 | N11: 27
A12: 179 | B12: Grupa-Mia-Exp1 ijakob | C12: 168 | H12: 2267 | I12: 179 | M12: 179 | N12: 27
A13: 180 | B13: Grupa-Mia-Exp1 lkaic | C13: 168 | H13: 2268 | I13: 180 | M13: 180 | N13: 27
... A25: 192 | B25: Grupa-Mia-Exp1 mzvonkovic | C25: 168 | H25: 2280 | I25: 192 | M25: 192 | N25: 27
F27: Eksperiment 2, 3.3.2016. 3 razred Likovni Crtanje promatranjem Mia
A28: 193 | B28: Grupa-Mia-Exp2-1 | C28: 168 | F28: ANTONIJA | G28: BUČKAL | H28: 2257 | I28: 193 | J28: Grupa-Mia-Exp2-1 | M28: 193 | N28: 28
A29: 194 | B29: Grupa-Mia-Exp2-2 | C29: 168 | F29: LORENA | G29: DOMANČIĆ | H29: 2258 | I29: 194 | J29: Grupa-Mia-Exp2-2 | M29: 194 | N29: 28
A30: 195 | B30: Grupa-Mia-Exp2-3 | C30: 168 | F30: LEA | G30: DVOJKOVIĆ | H30: 2259 | I30: 195 | J30: Grupa-Mia-Exp2-3 | M30: 195 | N30: 28
A31: 196 | B31: Grupa-Mia-Exp2-4 | C31: 168 | F31: TONKA | G31: FERDEBAR | H31: 2260 | I31: 196 | J31: Grupa-Mia-Exp2-4 | M31: 196 | N31: 28
A32: 197 | B32: Grupa-Mia-Exp2-5 | C32: 168 | F32: ANDELON | G32: FILOTAŠ | H32: 2261 | I32: 197 | J32: Grupa-Mia-Exp2-5 | M32: 197 | N32: 28
A33: 198 | B33: Grupa-Mia-Exp2-6 | C33: 168 | F33: LUKA | G33: FRANIĆ | H33: 2262 | I33: 198 | J33: Grupa-Mia-Exp2-6 | M33: 198 | N33: 28
A34: 199 | B34: Grupa-Mia-Exp2-7 | C34: 168 | F34: FRAN | G34: GLAS | H34: 2263 | I34: 199 | J34: Grupa-Mia-Exp2-7 | M34: 199 | N34: 28
A35: 200 | B35: Grupa-Mia-Exp2-8 | C35: 168 | F35: GITA | G35: HAINSKI | H35: 2264 | I35: 200 | J35: Grupa-Mia-Exp2-8 | M35: 200 | N35: 28
A36: 201 | B36: Grupa-Mia-Exp2-9 | C36: 168 | F36: MIA | G36: HRANILOVIĆ | H36: 2265 | I36: 201 | J36: Grupa-Mia-Exp2-9 | M36: 201 | N36: 28
A37: 202 | B37: Grupa-Mia-Exp2-10 | C37: 168 | F37: GABRIELA | G37: JAGAR | H37: 2266 | I37: 202 | J37: Grupa-Mia-Exp2-10 | M37: 202 | N37: 28
A38: 203 | B38: Grupa-Mia-Exp2-11 | C38: 168 | F38: ISKRA | G38: JAKOB | H38: 2267 | I38: 203 | J38: Grupa-Mia-Exp2-11 | M38: 203 | N38: 28
A39: 204 | B39: Grupa-Mia-Exp2-12 | C39: 168 | F39: LOVRO | G39: KAIĆ | H39: 2268 | I39: 204 | J39: Grupa-Mia-Exp2-12 | M39: 204 | N39: 28
F40: OMAR | G40: KARALIĆ | H40: 2269 | I40: 193 | J40: Grupa-Mia-Exp2-1
F41: LEON | G41: MATE | H41: 2270 | I41: 194 | J41: Grupa-Mia-Exp2-2
F42: DAVID | G42: MATOŠEVIĆ | H42: 2271 | I42: 195 | J42: Grupa-Mia-Exp2-3
F43: LUNA | G43: MAVRA | H43: 2272 | I43: 196 | J43: Grupa-Mia-Exp2-4
F44: MAGDALENA | G44: MIHALJEVIĆ | H44: 2273 | I44: 197 | J44: Grupa-Mia-Exp2-5
F45: MARTA | G45: PERESTEGI | H45: 2274 | I45: 198 | J45: Grupa-Mia-Exp2-6
F46: IVY | G46: PRELOG | H46: 2275 | I46: 199 | J46: Grupa-Mia-Exp2-7
F47: LEA | G47: SHEK BRNARDIĆ | H47: 2276 | I47: 200 | J47: Grupa-Mia-Exp2-8
F48: MARIN | G48: ŠTEKO | H48: 2277 | I48: 201 | J48: Grupa-Mia-Exp2-9
F49: LOVRO | G49: ŠUK | H49: 2278 | I49: 202 | J49: Grupa-Mia-Exp2-10
F50: FRANCISKA | G50: ZVONKOVIĆ | H50: 2279 | I50: 203 | J50: Grupa-Mia-Exp2-11
F51: MATEA | G51: ZVONKOVIĆ | H51: 2280 | I51: 204 | J51: Grupa-Mia-Exp2-12

Sheet Eksperimenti2_Mia-16.3.-1B
B1: Tablica Group | K1: UserGroup tablica
A2: ID | B2: GroupName | C2: ParentGroupID
A3: 224 | B3: Grupa-Mia-Exp2 aberc | C3: 166 | G3: 224 | H3: 30 | K3: 2217 | L3: 224
A4: 225 | B4: Grupa-Mia-Exp2 abiloglav | C4: 166 | G4: 225 | H4: 30 | K4: 2218 | L4: 225
A5: 226 | B5: Grupa-Mia-Exp2 ldurik | C5: 166 | G5: 226 | H5: 30 | K5: 2219 | L5: 226
A6: 227 | B6: Grupa-Mia-Exp2 eglavinic | C6: 166 | G6: 227 | H6: 30 | K6: 2220 | L6: 227
A7: 228 | B7: Grupa-Mia-Exp2 bhadzic | C7: 166 | G7: 228 | H7: 30 | K7: 2221 | L7: 228
A8: 229 | B8: Grupa-Mia-Exp2 aknezevic | C8: 166 | G8: 229 | H8: 30 | K8: 2222 | L8: 229
A9: 230 | B9: Grupa-Mia-Exp2 lmajer | C9: 166 | G9: 230 | H9: 30 | K9: 2223 | L9: 230
A10: 231 | B10: Grupa-Mia-Exp2 vmartinis | C10: 166 | G10: 231 | H10: 30 | K10: 2224 | L10: 231
A11: 232 | B11: Grupa-Mia-Exp2 nmate | C11: 166 | G11: 232 | H11: 30 | K11: 2225 | L11: 232
A12: 233 | B12: Grupa-Mia-Exp2 mmelher | C12: 166 | G12: 233 | H12: 30 | K12: 2226 | L12: 233
A13: 234 | B13: Grupa-Mia-Exp2 komrcanin | C13: 166 | G13: 234 | H13: 30 | K13: 2227 | L13: 234
A14: 235 | B14: Grupa-Mia-Exp2 josmak | C14: 166 | G14: 235 | H14: 30 | K14: 2228 | L14: 235
... A29: 248 | B29: Grupa-Mia-Exp2-8 | C29: 166 | G29: 248 | H29: 31 | K29: 2224 | L29: 248
K30: 2225 | L30: 241
K31: 2226 | L31: 242
K32: 2227 | L32: 243
K33: 2228 | L33: 244
K34: 2229 | L34: 245
K35: 2230 | L35: 246
K36: 2231 | L36: 247
K37: 2232 | L37: 248
K38: 2233 | L38: 241

Sheet Eksperimenti2_Mia-16.3.-1A
B1: Tablica Group | G1: GroupDrawingTaskGroup | K1: UserGroup tablica
A2: ID | B2: GroupName | C2: ParentGroupID
A3: 249 | B3: Grupa-Mia-Exp1 abesic | C3: 165 | G3: 249 | H3: 30 | K3: 2199 | L3: 249
A4: 250 | B4: Grupa-Mia-Exp1 dbukal | C4: 165 | G4: 250 | H4: 30 | K4: 2200 | L4: 250
A5: 251 | B5: Grupa-Mia-Exp1 gcikac | C5: 165 | G5: 251 | H5: 30 | K5: 2201 | L5: 251
A6: 252 | B6: Grupa-Mia-Exp1 ldobrijevic | C6: 165 | G6: 252 | H6: 30 | K6: 2202 | L6: 252
A7: 253 | B7: Grupa-Mia-Exp1 adzakula | C7: 165 | G7: 253 | H7: 30 | K7: 2203 | L7: 253
A8: 254 | B8: Grupa-Mia-Exp1 sfilotas | C8: 165 | G8: 254 | H8: 30 | K8: 2204 | L8: 254
A9: 255 | B9: Grupa-Mia-Exp1 ahrubi | C9: 165 | G9: 255 | H9: 30 | K9: 2205 | L9: 255
A10: 256 | B10: Grupa-Mia-Exp1 vjergovic | C10: 165 | G10: 256 | H10: 30 | K10: 2206 | L10: 256
A11: 257 | B11: Grupa-Mia-Exp1 kmatosevic | C11: 165 | G11: 257 | H11: 30 | K11: 2207 | L11: 257
A12: 258 | B12: Grupa-Mia-Exp1 bmikovic | C12: 165 | G12: 258 | H12: 30 | K12: 2208 | L12: 258
A13: 259 | B13: Grupa-Mia-Exp1 fperestegi | C13: 165 | G13: 259 | H13: 30 | K13: 2209 | L13: 259
A14: 260 | B14: Grupa-Mia-Exp1 lshek | C14: 165 | G14: 260 | H14: 30 | K14: 2210 | L14: 260
... A20: 266 | B20: Grupa-Mia-Exp1 vzavrtnik | C20: 165 | G20: 266 | H20: 30 | K20: 2216 | L20: 266
